Workbook

Sheet Dashboard
A1: DASHBOARD —
A2: banca inicial
A3: 2160
A4: =$A$3+SUM(Registro!J5:J604) -> 2962.87 | C4: =IFERROR(SUM(Registro!J5:J604),0) -> 802.87 | E4: =IFERROR(C4/$A$3,0) -> 0.37169907 | G4: =COUNTIFS(Registro!A5:A604,"<>",Registro!B5:B604,"<>") -> 508 | I4: =IFERROR(AVERAGEIFS(Registro!F5:F604,Registro!I5:I604,"<>Pendiente",Registro!B5:B604,"<>"),0) -> 1.8058636 | K4: =IFERROR(AVERAGEIFS(Registro!G5:G604,Registro!I5:I604,"<>Pendiente",Registro!B5:B604,"<>"),0) -> 21.351779 | M4: =IFERROR(MIN(Registro!Q5:Q604),0) -> -158.62 | O4: =IFERROR(C4/SUMIF(Registro!I5:I604,"<>Pendiente",Registro!G5:G604),0) -> 0.074312292 | Q4: =IFERROR(M4/MAX(Registro!P5:P604),0) -> -0.05480143
A7: BANK ACTUAL (€) | C7: BENEFICIO TOTAL (€) | E7: ROI GLOBAL | G7: APUESTAS TOTALES | I7: CUOTA MEDIA | K7: STAKE MEDIO (€) | M7: DRAWDOWN MÁXIMO (€) | O7: YIELD | Q7: DRAWDOWN %
A9: RESUMEN POR CASA
A10: Casa | B10: Bank inicial (€) | C10: Beneficio (€) | D10: Bank actual (€) | E10: ROI casa | F10: Apuestas totales | G10: Ganadas | H10: Perdidas | I10: Anuladas | J10: Pendientes | K10: Win rate | L10: Cuota media | M10: Stake medio (€) | N10: Beneficio medio (€) | O10: Apuestas HOY | P10: Límite 10/día
A11: Winamax | B11: 260 | C11: =IFERROR(SUMIF(Registro!B$5:B$604,A11,Registro!J$5:J$604),0) -> 180.77 | D11: =B11+C11 -> 440.77 | E11: =IFERROR(C11/B11,0) -> 0.69526923 | F11: =COUNTIFS(Registro!B$5:B$604,A11,Registro!A$5:A$604,"<>") -> 100 | G11: =COUNTIFS(Registro!B$5:B$604,A11,Registro!I$5:I$604,"Ganada") -> 54 | H11: =COUNTIFS(Registro!B$5:B$604,A11,Registro!I$5:I$604,"Perdida") -> 37 | I11: =COUNTIFS(Registro!B$5:B$604,A11,Registro!I$5:I$604,"Anulada") -> 8 | J11: =COUNTIFS(Registro!B$5:B$604,A11,Registro!I$5:I$604,"Pendiente") -> 1 | K11: =IFERROR(G11/(G11+H11),0) -> 0.59340659 | L11: =IFERROR(AVERAGEIFS(Registro!F$5:F$604,Registro!B$5:B$604,A11),0) -> 1.7805 | M11: =IFERROR(AVERAGEIFS(Registro!G$5:G$604,Registro!B$5:B$604,A11),0) -> 23.89 | N11: =IFERROR(AVERAGEIFS(Registro!J$5:J$604,Registro!B$5:B$604,A11,Registro!I$5:I$604,"<>Pendiente"),0) -> 1.8259596 | O11: =COUNTIFS(Registro!B$5:B$604,A11,Registro!A$5:A$604,TODAY()) -> 6 | P11: =IF(O11>=10,"🔴 LÍMITE",IF(O11>=8,"🟠 CERCA","🟢 OK")) -> 🟢 OK
A12: Yosport | B12: 200 | C12: =IFERROR(SUMIF(Registro!B$5:B$604,A12,Registro!J$5:J$604),0) -> 108.84 | D12: =B12+C12 -> 308.84 | E12: =IFERROR(C12/B12,0) -> 0.5442 | F12: =COUNTIFS(Registro!B$5:B$604,A12,Registro!A$5:A$604,"<>") -> 24 | G12: =COUNTIFS(Registro!B$5:B$604,A12,Registro!I$5:I$604,"Ganada") -> 19 | H12: =COUNTIFS(Registro!B$5:B$604,A12,Registro!I$5:I$604,"Perdida") -> 5 | I12: =COUNTIFS(Registro!B$5:B$604,A12,Registro!I$5:I$604,"Anulada") -> 0 | J12: =COUNTIFS(Registro!B$5:B$604,A12,Registro!I$5:I$604,"Pendiente") -> 0 | K12: =IFERROR(G12/(G12+H12),0) -> 0.79166667 | L12: =IFERROR(AVERAGEIFS(Registro!F$5:F$604,Registro!B$5:B$604,A12),0) -> 1.5995833 | M12: =IFERROR(AVERAGEIFS(Registro!G$5:G$604,Registro!B$5:B$604,A12),0) -> 21.083333 | N12: =IFERROR(AVERAGEIFS(Registro!J$5:J$604,Registro!B$5:B$604,A12,Registro!I$5:I$604,"<>Pendiente"),0) -> 4.535 | O12: =COUNTIFS(Registro!B$5:B$604,A12,Registro!A$5:A$604,TODAY()) -> 0 | P12: =IF(O12>=10,"🔴 LÍMITE",IF(O12>=8,"🟠 CERCA","🟢 OK")) -> 🟢 OK
A13: Paf | B13: 200 | C13: =IFERROR(SUMIF(Registro!B$5:B$604,A13,Registro!J$5:J$604),0) -> 51.42 | D13: =B13+C13 -> 251.42 | E13: =IFERROR(C13/B13,0) -> 0.2571 | F13: =COUNTIFS(Registro!B$5:B$604,A13,Registro!A$5:A$604,"<>") -> 100 | G13: =COUNTIFS(Registro!B$5:B$604,A13,Registro!I$5:I$604,"Ganada") -> 58 | H13: =COUNTIFS(Registro!B$5:B$604,A13,Registro!I$5:I$604,"Perdida") -> 39 | I13: =COUNTIFS(Registro!B$5:B$604,A13,Registro!I$5:I$604,"Anulada") -> 3 | J13: =COUNTIFS(Registro!B$5:B$604,A13,Registro!I$5:I$604,"Pendiente") -> 0 | K13: =IFERROR(G13/(G13+H13),0) -> 0.59793814 | L13: =IFERROR(AVERAGEIFS(Registro!F$5:F$604,Registro!B$5:B$604,A13),0) -> 1.7959 | M13: =IFERROR(AVERAGEIFS(Registro!G$5:G$604,Registro!B$5:B$604,A13),0) -> 20.79 | N13: =IFERROR(AVERAGEIFS(Registro!J$5:J$604,Registro!B$5:B$604,A13,Registro!I$5:I$604,"<>Pendiente"),0) -> 0.5142 | O13: =COUNTIFS(Registro!B$5:B$604,A13,Registro!A$5:A$604,TODAY()) -> 10 | P13: =IF(O13>=10,"🔴 LÍMITE",IF(O13>=8,"🟠 CERCA","🟢 OK")) -> 🔴 LÍMITE
A14: Pokerstars | B14: 200 | C14: =IFERROR(SUMIF(Registro!B$5:B$604,A14,Registro!J$5:J$604),0) -> 128.46 | D14: =B14+C14 -> 328.46 | E14: =IFERROR(C14/B14,0) -> 0.6423 | F14: =COUNTIFS(Registro!B$5:B$604,A14,Registro!A$5:A$604,"<>") -> 57 | G14: =COUNTIFS(Registro!B$5:B$604,A14,Registro!I$5:I$604,"Ganada") -> 33 | H14: =COUNTIFS(Registro!B$5:B$604,A14,Registro!I$5:I$604,"Perdida") -> 24 | I14: =COUNTIFS(Registro!B$5:B$604,A14,Registro!I$5:I$604,"Anulada") -> 0 | J14: =COUNTIFS(Registro!B$5:B$604,A14,Registro!I$5:I$604,"Pendiente") -> 0 | K14: =IFERROR(G14/(G14+H14),0) -> 0.57894737 | L14: =IFERROR(AVERAGEIFS(Registro!F$5:F$604,Registro!B$5:B$604,A14),0) -> 1.9115789 | M14: =IFERROR(AVERAGEIFS(Registro!G$5:G$604,Registro!B$5:B$604,A14),0) -> 16.526316 | N14: =IFERROR(AVERAGEIFS(Registro!J$5:J$604,Registro!B$5:B$604,A14,Registro!I$5:I$604,"<>Pendiente"),0) -> 2.2536842 | O14: =COUNTIFS(Registro!B$5:B$604,A14,Registro!A$5:A$604,TODAY()) -> 3 | P14: =IF(O14>=10,"🔴 LÍMITE",IF(O14>=8,"🟠 CERCA","🟢 OK")) -> 🟢 OK
A15: Sportium | B15: 100 | C15: =IFERROR(SUMIF(Registro!B$5:B$604,A15,Registro!J$5:J$604),0) -> 169.8 | D15: =B15+C15 -> 269.8 | E15: =IFERROR(C15/B15,0) -> 1.698 | F15: =COUNTIFS(Registro!B$5:B$604,A15,Registro!A$5:A$604,"<>") -> 74 | G15: =COUNTIFS(Registro!B$5:B$604,A15,Registro!I$5:I$604,"Ganada") -> 46 | H15: =COUNTIFS(Registro!B$5:B$604,A15,Registro!I$5:I$604,"Perdida") -> 26 | I15: =COUNTIFS(Registro!B$5:B$604,A15,Registro!I$5:I$604,"Anulada") -> 2 | J15: =COUNTIFS(Registro!B$5:B$604,A15,Registro!I$5:I$604,"Pendiente") -> 0 | K15: =IFERROR(G15/(G15+H15),0) -> 0.63888889 | L15: =IFERROR(AVERAGEIFS(Registro!F$5:F$604,Registro!B$5:B$604,A15),0) -> 1.7429324 | M15: =IFERROR(AVERAGEIFS(Registro!G$5:G$604,Registro!B$5:B$604,A15),0) -> 22.72973 | N15: =IFERROR(AVERAGEIFS(Registro!J$5:J$604,Registro!B$5:B$604,A15,Registro!I$5:I$604,"<>Pendiente"),0) -> 2.2945946 | O15: =COUNTIFS(Registro!B$5:B$604,A15,Registro!A$5:A$604,TODAY()) -> 2 | P15: =IF(O15>=10,"🔴 LÍMITE",IF(O15>=8,"🟠 CERCA","🟢 OK")) -> 🟢 OK
A16: SpeedyBet | B16: 100 | C16: =IFERROR(SUMIF(Registro!B$5:B$604,A16,Registro!J$5:J$604),0) -> -88.3 | D16: =B16+C16 -> 11.7 | E16: =IFERROR(C16/B16,0) -> -0.883 | F16: =COUNTIFS(Registro!B$5:B$604,A16,Registro!A$5:A$604,"<>") -> 61 | G16: =COUNTIFS(Registro!B$5:B$604,A16,Registro!I$5:I$604,"Ganada") -> 32 | H16: =COUNTIFS(Registro!B$5:B$604,A16,Registro!I$5:I$604,"Perdida") -> 28 | I16: =COUNTIFS(Registro!B$5:B$604,A16,Registro!I$5:I$604,"Anulada") -> 0 | J16: =COUNTIFS(Registro!B$5:B$604,A16,Registro!I$5:I$604,"Pendiente") -> 1 | K16: =IFERROR(G16/(G16+H16),0) -> 0.53333333 | L16: =IFERROR(AVERAGEIFS(Registro!F$5:F$604,Registro!B$5:B$604,A16),0) -> 1.8413115 | M16: =IFERROR(AVERAGEIFS(Registro!G$5:G$604,Registro!B$5:B$604,A16),0) -> 20.47541 | N16: =IFERROR(AVERAGEIFS(Registro!J$5:J$604,Registro!B$5:B$604,A16,Registro!I$5:I$604,"<>Pendiente"),0) -> -1.4716667 | O16: =COUNTIFS(Registro!B$5:B$604,A16,Registro!A$5:A$604,TODAY()) -> 2 | P16: =IF(O16>=10,"🔴 LÍMITE",IF(O16>=8,"🟠 CERCA","🟢 OK")) -> 🟢 OK
A17: Casumo | B17: 17.69 | C17: =IFERROR(SUMIF(Registro!B$5:B$604,A17,Registro!J$5:J$604),0) -> 166.3 | D17: =B17+C17 -> 183.99 | E17: =IFERROR(C17/B17,0) -> 9.4007914 | F17: =COUNTIFS(Registro!B$5:B$604,A17,Registro!A$5:A$604,"<>") -> 20 | G17: =COUNTIFS(Registro!B$5:B$604,A17,Registro!I$5:I$604,"Ganada") -> 16 | H17: =COUNTIFS(Registro!B$5:B$604,A17,Registro!I$5:I$604,"Perdida") -> 3 | I17: =COUNTIFS(Registro!B$5:B$604,A17,Registro!I$5:I$604,"Anulada") -> 1 | J17: =COUNTIFS(Registro!B$5:B$604,A17,Registro!I$5:I$604,"Pendiente") -> 0 | K17: =IFERROR(G17/(G17+H17),0) -> 0.84210526 | L17: =IFERROR(AVERAGEIFS(Registro!F$5:F$604,Registro!B$5:B$604,A17),0) -> 1.594 | M17: =IFERROR(AVERAGEIFS(Registro!G$5:G$604,Registro!B$5:B$604,A17),0) -> 28.8 | N17: =IFERROR(AVERAGEIFS(Registro!J$5:J$604,Registro!B$5:B$604,A17,Registro!I$5:I$604,"<>Pendiente"),0) -> 8.315 | O17: =COUNTIFS(Registro!B$5:B$604,A17,Registro!A$5:A$604,TODAY()) -> 0 | P17: =IF(O17>=10,"🔴 LÍMITE",IF(O17>=8,"🟠 CERCA","🟢 OK")) -> 🟢 OK
A18: Retabet | B18: 0 | C18: =IFERROR(SUMIF(Registro!B$5:B$604,A18,Registro!J$5:J$604),0) -> 0 | D18: =B18+C18 -> 0 | E18: =IFERROR(C18/B18,0) -> 0 | F18: =COUNTIFS(Registro!B$5:B$604,A18,Registro!A$5:A$604,"<>") -> 0 | G18: =COUNTIFS(Registro!B$5:B$604,A18,Registro!I$5:I$604,"Ganada") -> 0 | H18: =COUNTIFS(Registro!B$5:B$604,A18,Registro!I$5:I$604,"Perdida") -> 0 | I18: =COUNTIFS(Registro!B$5:B$604,A18,Registro!I$5:I$604,"Anulada") -> 0 | J18: =COUNTIFS(Registro!B$5:B$604,A18,Registro!I$5:I$604,"Pendiente") -> 0 | K18: =IFERROR(G18/(G18+H18),0) -> 0 | L18: =IFERROR(AVERAGEIFS(Registro!F$5:F$604,Registro!B$5:B$604,A18),0) -> 0 | M18: =IFERROR(AVERAGEIFS(Registro!G$5:G$604,Registro!B$5:B$604,A18),0) -> 0 | N18: =IFERROR(AVERAGEIFS(Registro!J$5:J$604,Registro!B$5:B$604,A18,Registro!I$5:I$604,"<>Pendiente"),0) -> 0 | O18: =COUNTIFS(Registro!B$5:B$604,A18,Registro!A$5:A$604,TODAY()) -> 0 | P18: =IF(O18>=10,"🔴 LÍMITE",IF(O18>=8,"🟠 CERCA","🟢 OK")) -> 🟢 OK
A19: GoldenBull | B19: 100 | C19: =IFERROR(SUMIF(Registro!B$5:B$604,A19,Registro!J$5:J$604),0) -> 133.4 | D19: =B19+C19 -> 233.4 | E19: =IFERROR(C19/B19,0) -> 1.334 | F19: =COUNTIFS(Registro!B$5:B$604,A19,Registro!A$5:A$604,"<>") -> 64 | G19: =COUNTIFS(Registro!B$5:B$604,A19,Registro!I$5:I$604,"Ganada") -> 39 | H19: =COUNTIFS(Registro!B$5:B$604,A19,Registro!I$5:I$604,"Perdida") -> 25 | I19: =COUNTIFS(Registro!B$5:B$604,A19,Registro!I$5:I$604,"Anulada") -> 0 | J19: =COUNTIFS(Registro!B$5:B$604,A19,Registro!I$5:I$604,"Pendiente") -> 0 | K19: =IFERROR(G19/(G19+H19),0) -> 0.609375 | L19: =IFERROR(AVERAGEIFS(Registro!F$5:F$604,Registro!B$5:B$604,A19),0) -> 1.915625 | M19: =IFERROR(AVERAGEIFS(Registro!G$5:G$604,Registro!B$5:B$604,A19),0) -> 20.328125 | N19: =IFERROR(AVERAGEIFS(Registro!J$5:J$604,Registro!B$5:B$604,A19,Registro!I$5:I$604,"<>Pendiente"),0) -> 2.084375 | O19: =COUNTIFS(Registro!B$5:B$604,A19,Registro!A$5:A$604,TODAY()) -> 0 | P19: =IF(O19>=10,"🔴 LÍMITE",IF(O19>=8,"🟠 CERCA","🟢 OK")) -> 🟢 OK
A20: Bet365 | B20: 55 | C20: =IFERROR(SUMIF(Registro!B$5:B$604,A20,Registro!J$5:J$604),0) -> -47.82 | D20: =B20+C20 -> 7.18 | F20: =COUNTIFS(Registro!B$5:B$604,A20,Registro!A$5:A$604,"<>") -> 8 | G20: =COUNTIFS(Registro!B$5:B$604,A20,Registro!I$5:I$604,"Ganada") -> 3 | H20: =COUNTIFS(Registro!B$5:B$604,A20,Registro!I$5:I$604,"Perdida") -> 4 | I20: =COUNTIFS(Registro!B$5:B$604,A20,Registro!I$5:I$604,"Anulada") -> 1 | J20: =COUNTIFS(Registro!B$5:B$604,A20,Registro!I$5:I$604,"Pendiente") -> 0 | K20: =IFERROR(G20/(G20+H20),0) -> 0.42857143 | L20: =IFERROR(AVERAGEIFS(Registro!F$5:F$604,Registro!B$5:B$604,A20),0) -> 2.03375 | M20: =IFERROR(AVERAGEIFS(Registro!G$5:G$604,Registro!B$5:B$604,A20),0) -> 17.5 | N20: =IFERROR(AVERAGEIFS(Registro!J$5:J$604,Registro!B$5:B$604,A20,Registro!I$5:I$604,"<>Pendiente"),0) -> -5.9775 | O20: =COUNTIFS(Registro!B$5:B$604,A20,Registro!A$5:A$604,TODAY()) -> 0 | P20: =IF(O20>=10,"🔴 LÍMITE",IF(O20>=8,"🟠 CERCA","🟢 OK")) -> 🟢 OK
A21: Botemania | B21: 0 | C21: =IFERROR(SUMIF(Registro!B$5:B$604,A21,Registro!J$5:J$604),0) -> 0 | D21: =B21+C21 -> 0 | E21: =IFERROR(C21/B21,0) -> 0 | F21: =COUNTIFS(Registro!B$5:B$604,A21,Registro!A$5:A$604,"<>") -> 0 | G21: =COUNTIFS(Registro!B$5:B$604,A21,Registro!I$5:I$604,"Ganada") -> 0 | H21: =COUNTIFS(Registro!B$5:B$604,A21,Registro!I$5:I$604,"Perdida") -> 0 | I21: =COUNTIFS(Registro!B$5:B$604,A21,Registro!I$5:I$604,"Anulada") -> 0 | J21: =COUNTIFS(Registro!B$5:B$604,A21,Registro!I$5:I$604,"Pendiente") -> 0 | K21: =IFERROR(G21/(G21+H21),0) -> 0 | L21: =IFERROR(AVERAGEIFS(Registro!F$5:F$604,Registro!B$5:B$604,A21),0) -> 0 | M21: =IFERROR(AVERAGEIFS(Registro!G$5:G$604,Registro!B$5:B$604,A21),0) -> 0 | N21: =IFERROR(AVERAGEIFS(Registro!J$5:J$604,Registro!B$5:B$604,A21,Registro!I$5:I$604,"<>Pendiente"),0) -> 0 | O21: =COUNTIFS(Registro!B$5:B$604,A21,Registro!A$5:A$604,TODAY()) -> 0 | P21: =IF(O21>=10,"🔴 LÍMITE",IF(O21>=8,"🟠 CERCA","🟢 OK")) -> 🟢 OK
A22: Paston | B22: 0 | C22: =IFERROR(SUMIF(Registro!B$5:B$604,A22,Registro!J$5:J$604),0) -> 0 | D22: =B22+C22 -> 0 | E22: =IFERROR(C22/B22,0) -> 0 | F22: =COUNTIFS(Registro!B$5:B$604,A22,Registro!A$5:A$604,"<>") -> 0 | G22: =COUNTIFS(Registro!B$5:B$604,A22,Registro!I$5:I$604,"Ganada") -> 0 | H22: =COUNTIFS(Registro!B$5:B$604,A22,Registro!I$5:I$604,"Perdida") -> 0 | I22: =COUNTIFS(Registro!B$5:B$604,A22,Registro!I$5:I$604,"Anulada") -> 0 | J22: =COUNTIFS(Registro!B$5:B$604,A22,Registro!I$5:I$604,"Pendiente") -> 0 | K22: =IFERROR(G22/(G22+H22),0) -> 0 | L22: =IFERROR(AVERAGEIFS(Registro!F$5:F$604,Registro!B$5:B$604,A22),0) -> 0 | M22: =IFERROR(AVERAGEIFS(Registro!G$5:G$604,Registro!B$5:B$604,A22),0) -> 0 | N22: =IFERROR(AVERAGEIFS(Registro!J$5:J$604,Registro!B$5:B$604,A22,Registro!I$5:I$604,"<>Pendiente"),0) -> 0 | O22: =COUNTIFS(Registro!B$5:B$604,A22,Registro!A$5:A$604,TODAY()) -> 0 | P22: =IF(O22>=10,"🔴 LÍMITE",IF(O22>=8,"🟠 CERCA","🟢 OK")) -> 🟢 OK
A23: Casino Gran Madrid | B23: 0 | C23: =IFERROR(SUMIF(Registro!B$5:B$604,A23,Registro!J$5:J$604),0) -> 0 | D23: =B23+C23 -> 0 | E23: =IFERROR(C23/B23,0) -> 0 | F23: =COUNTIFS(Registro!B$5:B$604,A23,Registro!A$5:A$604,"<>") -> 0 | G23: =COUNTIFS(Registro!B$5:B$604,A23,Registro!I$5:I$604,"Ganada") -> 0 | H23: =COUNTIFS(Registro!B$5:B$604,A23,Registro!I$5:I$604,"Perdida") -> 0 | I23: =COUNTIFS(Registro!B$5:B$604,A23,Registro!I$5:I$604,"Anulada") -> 0 | J23: =COUNTIFS(Registro!B$5:B$604,A23,Registro!I$5:I$604,"Pendiente") -> 0 | K23: =IFERROR(G23/(G23+H23),0) -> 0 | L23: =IFERROR(AVERAGEIFS(Registro!F$5:F$604,Registro!B$5:B$604,A23),0) -> 0 | M23: =IFERROR(AVERAGEIFS(Registro!G$5:G$604,Registro!B$5:B$604,A23),0) -> 0 | N23: =IFERROR(AVERAGEIFS(Registro!J$5:J$604,Registro!B$5:B$604,A23,Registro!I$5:I$604,"<>Pendiente"),0) -> 0 | O23: =COUNTIFS(Registro!B$5:B$604,A23,Registro!A$5:A$604,TODAY()) -> 0 | P23: =IF(O23>=10,"🔴 LÍMITE",IF(O23>=8,"🟠 CERCA","🟢 OK")) -> 🟢 OK
A24: TOTAL | B24: =SUM(B11:B23) -> 1232.69 | C24: =SUM(C11:C23) -> 802.87 | D24: =B24+C24 -> 2035.56 | E24: =IFERROR(C24/$A$3,0) -> 0.37169907 | F24: =SUM(F11:F23) -> 508 | G24: =SUM(G11:G23) -> 300 | H24: =SUM(H11:H23) -> 191 | I24: =SUM(I11:I23) -> 15 | J24: =SUM(J11:J23) -> 2 | K24: =IFERROR(G24/(G24+H24),0) -> 0.61099796 | L24: =IFERROR(AVERAGEIFS(Registro!F5:F604,Registro!I5:I604,"<>Pendiente"),0) -> 1.8058636 | M24: =IFERROR(AVERAGEIFS(Registro!G5:G604,Registro!I5:I604,"<>Pendiente"),0) -> 21.351779 | N24: =IFERROR(AVERAGEIFS(Registro!J5:J604,Registro!I5:I604,"<>Pendiente"),0) -> 1.5866996 | O24: =SUM(O11:O23) -> 23
A25: 🏦 Banco (reserva) | B25: =$A$3-B24 -> 927.31 | C25: ← actualiza A3 cuando hagas ingresos
K46: 1.8
B56: Columna1
J75: Columna1

Sheet Registro
A1: REGISTRO DE APUESTAS
A2: Bank global: 1.800€ | 9 casas x 200€ | Máx. 10 apuestas/día/casa
A4: Fecha | B4: Casa | C4: Evento | D4: Mercado | E4: Selección | F4: Cuota | G4: Stake (€) | H4: Tipo | I4: Resultado | J4: Beneficio (€) | K4: Bank acum. (€) | L4: ROI apuesta | M4: Apuestas hoy (casa) | N4: Notas | O4: Nº apuesta | P4: Bank máx. acum. (€) | Q4: Drawdown (€) | R4: Importe Cash Out (€) | S4: EV+ por apuesta (€) | T4: EV+ acumulado (€)
A5: 46194 | B5: Paf | C5: Egersund - Haugesund | D5: Totales O/U | E5: corners: Menos de 10.5 | F5: 1.86 | G5: 15 | H5: Normal | I5: Ganada | J5: =IF($A5="","",IF($I5="Ganada",ROUND($G5*($F5-1),2),IF($I5="Medio Ganada",ROUND($G5/2*($F5-1),2),IF($I5="Perdida",IF($H5="Free Bet",0,-$G5),IF($I5="Medio Perdida",IF($H5="Free Bet",0,-$G5/2),IF($I5="Reembolso",IF($R5="","",ROUND($R5-$G5,2)),IF($I5="Anulada",0,""))))))) -> 12.9 | K5: =IF(J5="","",2000+SUM(J$5:J5)) -> 2012.9 | L5: =IF(OR($I5="Ganada",$I5="Perdida",$I5="Medio Ganada",$I5="Medio Perdida"),IF($G5=0,"",J5/$G5),"") -> 0.86 | M5: =IF(OR($A5="",$B5=""),"",COUNTIFS($A$5:A5,A5,$B$5:B5,B5)) -> 1 | N5: =IF($A5="","",COUNTA($A$5:$A5)) -> 1 | O5: =IF($A5="","",COUNTA($A$5:$A5)) -> 1 | P5: =IF($K5="","",MAX($K$5:K5)) -> 2012.9 | Q5: =IF($K5="","",K5-P5) -> 0 | S5: =IF(OR($A5="",$F5=""),"",IF($I5="Pendiente","",ROUND($G5*($F5*0.609-1),2))) -> 1.99 | T5: =IF($A5="","",IFERROR(SUM($S$5:S5),0)) -> 1.99
A6: 46194 | B6: Paf | C6: Raufoss - Sogndal | D6: Totales O/U | E6: corners: Más de 9.5 | F6: 1.87 | G6: 15 | H6: Normal | I6: Ganada | J6: =IF($A6="","",IF($I6="Ganada",ROUND($G6*($F6-1),2),IF($I6="Medio Ganada",ROUND($G6/2*($F6-1),2),IF($I6="Perdida",IF($H6="Free Bet",0,-$G6),IF($I6="Medio Perdida",IF($H6="Free Bet",0,-$G6/2),IF($I6="Reembolso",IF($R6="","",ROUND($R6-$G6,2)),IF($I6="Anulada",0,""))))))) -> 13.05 | K6: =IF(J6="","",2000+SUM(J$5:J6)) -> 2025.95 | L6: =IF(OR($I6="Ganada",$I6="Perdida",$I6="Medio Ganada",$I6="Medio Perdida"),IF($G6=0,"",J6/$G6),"") -> 0.87 | M6: =IF(OR($A6="",$B6=""),"",COUNTIFS($A$5:A6,A6,$B$5:B6,B6)) -> 2 | N6: =IF($A6="","",COUNTA($A$5:$A6)) -> 2 | O6: =IF($A6="","",COUNTA($A$5:$A6)) -> 2 | P6: =IF($K6="","",MAX($K$5:K6)) -> 2025.95 | Q6: =IF($K6="","",K6-P6) -> 0 | S6: =IF(OR($A6="",$F6=""),"",IF($I6="Pendiente","",ROUND($G6*($F6*0.609-1),2))) -> 2.08 | T6: =IF($A6="","",IFERROR(SUM($S$5:S6),0)) -> 4.07
A7: 46194 | B7: Paf | C7: Strømmen - Stabæk | D7: Totales O/U | E7: corners: Menos de 11.5 | F7: 1.56 | G7: 20 | H7: Normal | I7: Perdida | J7: =IF($A7="","",IF($I7="Ganada",ROUND($G7*($F7-1),2),IF($I7="Medio Ganada",ROUND($G7/2*($F7-1),2),IF($I7="Perdida",IF($H7="Free Bet",0,-$G7),IF($I7="Medio Perdida",IF($H7="Free Bet",0,-$G7/2),IF($I7="Reembolso",IF($R7="","",ROUND($R7-$G7,2)),IF($I7="Anulada",0,""))))))) -> -20 | K7: =IF(J7="","",2000+SUM(J$5:J7)) -> 2005.95 | L7: =IF(OR($I7="Ganada",$I7="Perdida",$I7="Medio Ganada",$I7="Medio Perdida"),IF($G7=0,"",J7/$G7),"") -> -1 | M7: =IF(OR($A7="",$B7=""),"",COUNTIFS($A$5:A7,A7,$B$5:B7,B7)) -> 3 | N7: =IF($A7="","",COUNTA($A$5:$A7)) -> 3 | O7: =IF($A7="","",COUNTA($A$5:$A7)) -> 3 | P7: =IF($K7="","",MAX($K$5:K7)) -> 2025.95 | Q7: =IF($K7="","",K7-P7) -> -20 | S7: =IF(OR($A7="",$F7=""),"",IF($I7="Pendiente","",ROUND($G7*($F7*0.609-1),2))) -> -1 | T7: =IF($A7="","",IFERROR(SUM($S$5:S7),0)) -> 3.07
A8: 46194 | B8: Paf | C8: Strømmen - Stabæk | D8: 1X2/ML | E8: Strømmen | F8: 1.58 | G8: 20 | H8: Normal | I8: Ganada | J8: =IF($A8="","",IF($I8="Ganada",ROUND($G8*($F8-1),2),IF($I8="Medio Ganada",ROUND($G8/2*($F8-1),2),IF($I8="Perdida",IF($H8="Free Bet",0,-$G8),IF($I8="Medio Perdida",IF($H8="Free Bet",0,-$G8/2),IF($I8="Reembolso",IF($R8="","",ROUND($R8-$G8,2)),IF($I8="Anulada",0,""))))))) -> 11.6 | K8: =IF(J8="","",2000+SUM(J$5:J8)) -> 2017.55 | L8: =IF(OR($I8="Ganada",$I8="Perdida",$I8="Medio Ganada",$I8="Medio Perdida"),IF($G8=0,"",J8/$G8),"") -> 0.58 | M8: =IF(OR($A8="",$B8=""),"",COUNTIFS($A$5:A8,A8,$B$5:B8,B8)) -> 4 | N8: =IF($A8="","",COUNTA($A$5:$A8)) -> 4 | O8: =IF($A8="","",COUNTA($A$5:$A8)) -> 4 | P8: =IF($K8="","",MAX($K$5:K8)) -> 2025.95 | Q8: =IF($K8="","",K8-P8) -> -8.4 | S8: =IF(OR($A8="",$F8=""),"",IF($I8="Pendiente","",ROUND($G8*($F8*0.609-1),2))) -> -0.76 | T8: =IF($A8="","",IFERROR(SUM($S$5:S8),0)) -> 2.31
A9: 46194 | B9: Winamax | C9: crac go- tombense mg | D9: Totales O/U | E9: menos de 2 goles | F9: 2.1 | G9: 15 | H9: Normal | I9: Ganada | J9: =IF($A9="","",IF($I9="Ganada",ROUND($G9*($F9-1),2),IF($I9="Medio Ganada",ROUND($G9/2*($F9-1),2),IF($I9="Perdida",IF($H9="Free Bet",0,-$G9),IF($I9="Medio Perdida",IF($H9="Free Bet",0,-$G9/2),IF($I9="Reembolso",IF($R9="","",ROUND($R9-$G9,2)),IF($I9="Anulada",0,""))))))) -> 16.5 | K9: =IF(J9="","",2000+SUM(J$5:J9)) -> 2034.05 | L9: =IF(OR($I9="Ganada",$I9="Perdida",$I9="Medio Ganada",$I9="Medio Perdida"),IF($G9=0,"",J9/$G9),"") -> 1.1 | M9: =IF(OR($A9="",$B9=""),"",COUNTIFS($A$5:A9,A9,$B$5:B9,B9)) -> 1 | N9: =IF($A9="","",COUNTA($A$5:$A9)) -> 5 | O9: =IF($A9="","",COUNTA($A$5:$A9)) -> 5 | P9: =IF($K9="","",MAX($K$5:K9)) -> 2034.05 | Q9: =IF($K9="","",K9-P9) -> 0 | S9: =IF(OR($A9="",$F9=""),"",IF($I9="Pendiente","",ROUND($G9*($F9*0.609-1),2))) -> 4.18 | T9: =IF($A9="","",IFERROR(SUM($S$5:S9),0)) -> 6.49
A10: 46194 | B10: Winamax | C10: R.Safiullin-J.McCabe | D10: Totales O/U | E10: +22,5 juegos | F10: 2 | G10: 15 | H10: Normal | I10: Perdida | J10: =IF($A10="","",IF($I10="Ganada",ROUND($G10*($F10-1),2),IF($I10="Medio Ganada",ROUND($G10/2*($F10-1),2),IF($I10="Perdida",IF($H10="Free Bet",0,-$G10),IF($I10="Medio Perdida",IF($H10="Free Bet",0,-$G10/2),IF($I10="Reembolso",IF($R10="","",ROUND($R10-$G10,2)),IF($I10="Anulada",0,""))))))) -> -15 | K10: =IF(J10="","",2000+SUM(J$5:J10)) -> 2019.05 | L10: =IF(OR($I10="Ganada",$I10="Perdida",$I10="Medio Ganada",$I10="Medio Perdida"),IF($G10=0,"",J10/$G10),"") -> -1 | M10: =IF(OR($A10="",$B10=""),"",COUNTIFS($A$5:A10,A10,$B$5:B10,B10)) -> 2 | N10: =IF($A10="","",COUNTA($A$5:$A10)) -> 6 | O10: =IF($A10="","",COUNTA($A$5:$A10)) -> 6 | P10: =IF($K10="","",MAX($K$5:K10)) -> 2034.05 | Q10: =IF($K10="","",K10-P10) -> -15 | S10: =IF(OR($A10="",$F10=""),"",IF($I10="Pendiente","",ROUND($G10*($F10*0.609-1),2))) -> 3.27 | T10: =IF($A10="","",IFERROR(SUM($S$5:S10),0)) -> 9.76
A11: 46194 | B11: Winamax | C11: Andrade, Andres - Smith, Connor | D11: Totales O/U | E11: Total Under(21.5) - regular time | F11: 1.9 | G11: 15 | H11: Normal | I11: Perdida | J11: =IF($A11="","",IF($I11="Ganada",ROUND($G11*($F11-1),2),IF($I11="Medio Ganada",ROUND($G11/2*($F11-1),2),IF($I11="Perdida",IF($H11="Free Bet",0,-$G11),IF($I11="Medio Perdida",IF($H11="Free Bet",0,-$G11/2),IF($I11="Reembolso",IF($R11="","",ROUND($R11-$G11,2)),IF($I11="Anulada",0,""))))))) -> -15 | K11: =IF(J11="","",2000+SUM(J$5:J11)) -> 2004.05 | L11: =IF(OR($I11="Ganada",$I11="Perdida",$I11="Medio Ganada",$I11="Medio Perdida"),IF($G11=0,"",J11/$G11),"") -> -1 | M11: =IF(OR($A11="",$B11=""),"",COUNTIFS($A$5:A11,A11,$B$5:B11,B11)) -> 3 | N11: =IF($A11="","",COUNTA($A$5:$A11)) -> 7 | O11: =IF($A11="","",COUNTA($A$5:$A11)) -> 7 | P11: =IF($K11="","",MAX($K$5:K11)) -> 2034.05 | Q11: =IF($K11="","",K11-P11) -> -30 | S11: =IF(OR($A11="",$F11=""),"",IF($I11="Pendiente","",ROUND($G11*($F11*0.609-1),2))) -> 2.36 | T11: =IF($A11="","",IFERROR(SUM($S$5:S11),0)) -> 12.12
A12: 46194 | B12: Winamax | C12: Leones De Ponce - Osos de Manati | D12: 1X2/ML | E12: Team1 Win - with OT | F12: 1.66 | G12: 20 | H12: Normal | I12: Perdida | J12: =IF($A12="","",IF($I12="Ganada",ROUND($G12*($F12-1),2),IF($I12="Medio Ganada",ROUND($G12/2*($F12-1),2),IF($I12="Perdida",IF($H12="Free Bet",0,-$G12),IF($I12="Medio Perdida",IF($H12="Free Bet",0,-$G12/2),IF($I12="Reembolso",IF($R12="","",ROUND($R12-$G12,2)),IF($I12="Anulada",0,""))))))) -> -20 | K12: =IF(J12="","",2000+SUM(J$5:J12)) -> 1984.05 | L12: =IF(OR($I12="Ganada",$I12="Perdida",$I12="Medio Ganada",$I12="Medio Perdida"),IF($G12=0,"",J12/$G12),"") -> -1 | M12: =IF(OR($A12="",$B12=""),"",COUNTIFS($A$5:A12,A12,$B$5:B12,B12)) -> 4 | N12: =IF($A12="","",COUNTA($A$5:$A12)) -> 8 | O12: =IF($A12="","",COUNTA($A$5:$A12)) -> 8 | P12: =IF($K12="","",MAX($K$5:K12)) -> 2034.05 | Q12: =IF($K12="","",K12-P12) -> -50 | S12: =IF(OR($A12="",$F12=""),"",IF($I12="Pendiente","",ROUND($G12*($F12*0.609-1),2))) -> 0.22 | T12: =IF($A12="","",IFERROR(SUM($S$5:S12),0)) -> 12.34
A13: 46194 | B13: Winamax | C13: Independencia AC - Manauara AM | D13: Totales O/U | E13: Total Under(1) - 1s | F13: 2 | G13: 15 | H13: Normal | I13: Anulada | J13: =IF($A13="","",IF($I13="Ganada",ROUND($G13*($F13-1),2),IF($I13="Medio Ganada",ROUND($G13/2*($F13-1),2),IF($I13="Perdida",IF($H13="Free Bet",0,-$G13),IF($I13="Medio Perdida",IF($H13="Free Bet",0,-$G13/2),IF($I13="Reembolso",IF($R13="","",ROUND($R13-$G13,2)),IF($I13="Anulada",0,""))))))) -> 0 | K13: =IF(J13="","",2000+SUM(J$5:J13)) -> 1984.05 | L13: =IF(OR($I13="Ganada",$I13="Perdida",$I13="Medio Ganada",$I13="Medio Perdida"),IF($G13=0,"",J13/$G13),"") | M13: =IF(OR($A13="",$B13=""),"",COUNTIFS($A$5:A13,A13,$B$5:B13,B13)) -> 5 | N13: =IF($A13="","",COUNTA($A$5:$A13)) -> 9 | O13: =IF($A13="","",COUNTA($A$5:$A13)) -> 9 | P13: =IF($K13="","",MAX($K$5:K13)) -> 2034.05 | Q13: =IF($K13="","",K13-P13) -> -50 | S13: =IF(OR($A13="",$F13=""),"",IF($I13="Pendiente","",ROUND($G13*($F13*0.609-1),2))) -> 3.27 | T13: =IF($A13="","",IFERROR(SUM($S$5:S13),0)) -> 15.61
A14: 46194 | B14: Winamax | C14: Talleres Remedios - Comunicaciones | D14: DNB | E14: AH1(0.0)/DNB | F14: 1.34 | G14: 15 | H14: Normal | I14: Anulada | J14: =IF($A14="","",IF($I14="Ganada",ROUND($G14*($F14-1),2),IF($I14="Medio Ganada",ROUND($G14/2*($F14-1),2),IF($I14="Perdida",IF($H14="Free Bet",0,-$G14),IF($I14="Medio Perdida",IF($H14="Free Bet",0,-$G14/2),IF($I14="Reembolso",IF($R14="","",ROUND($R14-$G14,2)),IF($I14="Anulada",0,""))))))) -> 0 | K14: =IF(J14="","",2000+SUM(J$5:J14)) -> 1984.05 | L14: =IF(OR($I14="Ganada",$I14="Perdida",$I14="Medio Ganada",$I14="Medio Perdida"),IF($G14=0,"",J14/$G14),"") | M14: =IF(OR($A14="",$B14=""),"",COUNTIFS($A$5:A14,A14,$B$5:B14,B14)) -> 6 | N14: =IF($A14="","",COUNTA($A$5:$A14)) -> 10 | O14: =IF($A14="","",COUNTA($A$5:$A14)) -> 10 | P14: =IF($K14="","",MAX($K$5:K14)) -> 2034.05 | Q14: =IF($K14="","",K14-P14) -> -50 | S14: =IF(OR($A14="",$F14=""),"",IF($I14="Pendiente","",ROUND($G14*($F14*0.609-1),2))) -> -2.76 | T14: =IF($A14="","",IFERROR(SUM($S$5:S14),0)) -> 12.85
A15: 46194 | B15: Winamax | C15: Klugman, Hannah - Valentova, Tereza | D15: Totales O/U | E15: Total Over(19.5) | F15: 1.86 | G15: 15 | H15: Normal | I15: Ganada | J15: =IF($A15="","",IF($I15="Ganada",ROUND($G15*($F15-1),2),IF($I15="Medio Ganada",ROUND($G15/2*($F15-1),2),IF($I15="Perdida",IF($H15="Free Bet",0,-$G15),IF($I15="Medio Perdida",IF($H15="Free Bet",0,-$G15/2),IF($I15="Reembolso",IF($R15="","",ROUND($R15-$G15,2)),IF($I15="Anulada",0,""))))))) -> 12.9 | K15: =IF(J15="","",2000+SUM(J$5:J15)) -> 1996.95 | L15: =IF(OR($I15="Ganada",$I15="Perdida",$I15="Medio Ganada",$I15="Medio Perdida"),IF($G15=0,"",J15/$G15),"") -> 0.86 | M15: =IF(OR($A15="",$B15=""),"",COUNTIFS($A$5:A15,A15,$B$5:B15,B15)) -> 7 | N15: =IF($A15="","",COUNTA($A$5:$A15)) -> 11 | O15: =IF($A15="","",COUNTA($A$5:$A15)) -> 11 | P15: =IF($K15="","",MAX($K$5:K15)) -> 2034.05 | Q15: =IF($K15="","",K15-P15) -> -37.1 | S15: =IF(OR($A15="",$F15=""),"",IF($I15="Pendiente","",ROUND($G15*($F15*0.609-1),2))) -> 1.99 | T15: =IF($A15="","",IFERROR(SUM($S$5:S15),0)) -> 14.84
A16: 46194 | B16: Winamax | C16: Jay Clarke – Andrea Pellegrino | D16: Hándicap | E16: Hándicap asiático 2 4.5 juegos | F16: 1.7 | G16: 25 | H16: Normal | I16: Ganada | J16: =IF($A16="","",IF($I16="Ganada",ROUND($G16*($F16-1),2),IF($I16="Medio Ganada",ROUND($G16/2*($F16-1),2),IF($I16="Perdida",IF($H16="Free Bet",0,-$G16),IF($I16="Medio Perdida",IF($H16="Free Bet",0,-$G16/2),IF($I16="Reembolso",IF($R16="","",ROUND($R16-$G16,2)),IF($I16="Anulada",0,""))))))) -> 17.5 | K16: =IF(J16="","",2000+SUM(J$5:J16)) -> 2014.45 | L16: =IF(OR($I16="Ganada",$I16="Perdida",$I16="Medio Ganada",$I16="Medio Perdida"),IF($G16=0,"",J16/$G16),"") -> 0.7 | M16: =IF(OR($A16="",$B16=""),"",COUNTIFS($A$5:A16,A16,$B$5:B16,B16)) -> 8 | N16: =IF($A16="","",COUNTA($A$5:$A16)) -> 12 | O16: =IF($A16="","",COUNTA($A$5:$A16)) -> 12 | P16: =IF($K16="","",MAX($K$5:K16)) -> 2034.05 | Q16: =IF($K16="","",K16-P16) -> -19.6 | S16: =IF(OR($A16="",$F16=""),"",IF($I16="Pendiente","",ROUND($G16*($F16*0.609-1),2))) -> 0.88 | T16: =IF($A16="","",IFERROR(SUM($S$5:S16),0)) -> 15.72
... A96: 46199 | B96: Paf | C96: Vaprus Pärnu - Kuressaare FC | D96: Hándicap | E96: Asian Handicap2(1.5) - regular time | F96: 1.6 | G96: 23 | H96: Normal | I96: Ganada | J96: =IF($A96="","",IF($I96="Ganada",ROUND($G96*($F96-1),2),IF($I96="Medio Ganada",ROUND($G96/2*($F96-1),2),IF($I96="Perdida",IF($H96="Free Bet",0,-$G96),IF($I96="Medio Perdida",IF($H96="Free Bet",0,-$G96/2),IF($I96="Reembolso",IF($R96="","",ROUND($R96-$G96,2)),IF($I96="Anulada",0,""))))))) -> 13.8 | K96: =IF(J96="","",2000+SUM(J$5:J96)) -> 2338.51 | L96: =IF(OR($I96="Ganada",$I96="Perdida",$I96="Medio Ganada",$I96="Medio Perdida"),IF($G96=0,"",J96/$G96),"") -> 0.6 | M96: =IF(OR($A96="",$B96=""),"",COUNTIFS($A$5:A96,A96,$B$5:B96,B96)) -> 3 | N96: =IF($A96="","",COUNTA($A$5:$A96)) -> 92 | O96: =IF($A96="","",COUNTA($A$5:$A96)) -> 92 | P96: =IF($K96="","",MAX($K$5:K96)) -> 2338.51 | Q96: =IF($K96="","",K96-P96) -> 0 | S96: =IF(OR($A96="",$F96=""),"",IF($I96="Pendiente","",ROUND($G96*($F96*0.609-1),2))) -> -0.59 | T96: =IF($A96="","",IFERROR(SUM($S$5:S96),0)) -> 127.2
A97: 46199 | B97: Paf | C97: Liepajas Metalurgs - Rigas Futbola Skola | D97: 1X2/ML | E97: 2 | F97: 1.6 | G97: 23 | H97: Normal | I97: Ganada | J97: =IF($A97="","",IF($I97="Ganada",ROUND($G97*($F97-1),2),IF($I97="Medio Ganada",ROUND($G97/2*($F97-1),2),IF($I97="Perdida",IF($H97="Free Bet",0,-$G97),IF($I97="Medio Perdida",IF($H97="Free Bet",0,-$G97/2),IF($I97="Reembolso",IF($R97="","",ROUND($R97-$G97,2)),IF($I97="Anulada",0,""))))))) -> 13.8 | K97: =IF(J97="","",2000+SUM(J$5:J97)) -> 2352.31 | L97: =IF(OR($I97="Ganada",$I97="Perdida",$I97="Medio Ganada",$I97="Medio Perdida"),IF($G97=0,"",J97/$G97),"") -> 0.6 | M97: =IF(OR($A97="",$B97=""),"",COUNTIFS($A$5:A97,A97,$B$5:B97,B97)) -> 4 | N97: =IF($A97="","",COUNTA($A$5:$A97)) -> 93 | O97: =IF($A97="","",COUNTA($A$5:$A97)) -> 93 | P97: =IF($K97="","",MAX($K$5:K97)) -> 2352.31 | Q97: =IF($K97="","",K97-P97) -> 0 | S97: =IF(OR($A97="",$F97=""),"",IF($I97="Pendiente","",ROUND($G97*($F97*0.609-1),2))) -> -0.59 | T97: =IF($A97="","",IFERROR(SUM($S$5:S97),0)) -> 126.61
A98: 46199 | B98: Yosport | C98: Lucas Andrade Da Silva - Thiago Seyboth Wild | D98: Hándicap | E98: Asian Handicap1(2.5) - regular time | F98: 1.84 | G98: 17 | H98: Normal | I98: Ganada | J98: =IF($A98="","",IF($I98="Ganada",ROUND($G98*($F98-1),2),IF($I98="Medio Ganada",ROUND($G98/2*($F98-1),2),IF($I98="Perdida",IF($H98="Free Bet",0,-$G98),IF($I98="Medio Perdida",IF($H98="Free Bet",0,-$G98/2),IF($I98="Reembolso",IF($R98="","",ROUND($R98-$G98,2)),IF($I98="Anulada",0,""))))))) -> 14.28 | K98: =IF(J98="","",2000+SUM(J$5:J98)) -> 2366.59 | L98: =IF(OR($I98="Ganada",$I98="Perdida",$I98="Medio Ganada",$I98="Medio Perdida"),IF($G98=0,"",J98/$G98),"") -> 0.84 | M98: =IF(OR($A98="",$B98=""),"",COUNTIFS($A$5:A98,A98,$B$5:B98,B98)) -> 1 | N98: =IF($A98="","",COUNTA($A$5:$A98)) -> 94 | O98: =IF($A98="","",COUNTA($A$5:$A98)) -> 94 | P98: =IF($K98="","",MAX($K$5:K98)) -> 2366.59 | Q98: =IF($K98="","",K98-P98) -> 0 | S98: =IF(OR($A98="",$F98=""),"",IF($I98="Pendiente","",ROUND($G98*($F98*0.609-1),2))) -> 2.05 | T98: =IF($A98="","",IFERROR(SUM($S$5:S98),0)) -> 128.66
A99: 46199 | B99: Pokerstars | C99: Weiz - Marchfeld Mannsdorf Grossenzersdorf | D99: Hándicap | E99: European Handicap2(-2.0) | F99: 2 | G99: 17 | H99: Normal | I99: Perdida | J99: =IF($A99="","",IF($I99="Ganada",ROUND($G99*($F99-1),2),IF($I99="Medio Ganada",ROUND($G99/2*($F99-1),2),IF($I99="Perdida",IF($H99="Free Bet",0,-$G99),IF($I99="Medio Perdida",IF($H99="Free Bet",0,-$G99/2),IF($I99="Reembolso",IF($R99="","",ROUND($R99-$G99,2)),IF($I99="Anulada",0,""))))))) -> -17 | K99: =IF(J99="","",2000+SUM(J$5:J99)) -> 2349.59 | L99: =IF(OR($I99="Ganada",$I99="Perdida",$I99="Medio Ganada",$I99="Medio Perdida"),IF($G99=0,"",J99/$G99),"") -> -1 | M99: =IF(OR($A99="",$B99=""),"",COUNTIFS($A$5:A99,A99,$B$5:B99,B99)) -> 4 | N99: =IF($A99="","",COUNTA($A$5:$A99)) -> 95 | O99: =IF($A99="","",COUNTA($A$5:$A99)) -> 95 | P99: =IF($K99="","",MAX($K$5:K99)) -> 2366.59 | Q99: =IF($K99="","",K99-P99) -> -17 | S99: =IF(OR($A99="",$F99=""),"",IF($I99="Pendiente","",ROUND($G99*($F99*0.609-1),2))) -> 3.71 | T99: =IF($A99="","",IFERROR(SUM($S$5:S99),0)) -> 132.37
A100: 46199 | B100: Pokerstars | C100: Onsala BK - Landvetter IS | D100: 1X2/ML | E100: 1 | F100: 2.15 | G100: 17 | H100: Normal | I100: Perdida | J100: =IF($A100="","",IF($I100="Ganada",ROUND($G100*($F100-1),2),IF($I100="Medio Ganada",ROUND($G100/2*($F100-1),2),IF($I100="Perdida",IF($H100="Free Bet",0,-$G100),IF($I100="Medio Perdida",IF($H100="Free Bet",0,-$G100/2),IF($I100="Reembolso",IF($R100="","",ROUND($R100-$G100,2)),IF($I100="Anulada",0,""))))))) -> -17 | K100: =IF(J100="","",2000+SUM(J$5:J100)) -> 2332.59 | L100: =IF(OR($I100="Ganada",$I100="Perdida",$I100="Medio Ganada",$I100="Medio Perdida"),IF($G100=0,"",J100/$G100),"") -> -1 | M100: =IF(OR($A100="",$B100=""),"",COUNTIFS($A$5:A100,A100,$B$5:B100,B100)) -> 5 | N100: =IF($A100="","",COUNTA($A$5:$A100)) -> 96 | O100: =IF($A100="","",COUNTA($A$5:$A100)) -> 96 | P100: =IF($K100="","",MAX($K$5:K100)) -> 2366.59 | Q100: =IF($K100="","",K100-P100) -> -34 | S100: =IF(OR($A100="",$F100=""),"",IF($I100="Pendiente","",ROUND($G100*($F100*0.609-1),2))) -> 5.26 | T100: =IF($A100="","",IFERROR(SUM($S$5:S100),0)) -> 137.63
A101: 46199 | B101: GoldenBull | C101: Dundalk - Waterford FC | D101: Totales O/U | E101: Total Under(10.5) - Corners - regular time | F101: 1.93 | G101: 17 | H101: Normal | I101: Ganada | J101: =IF($A101="","",IF($I101="Ganada",ROUND($G101*($F101-1),2),IF($I101="Medio Ganada",ROUND($G101/2*($F101-1),2),IF($I101="Perdida",IF($H101="Free Bet",0,-$G101),IF($I101="Medio Perdida",IF($H101="Free Bet",0,-$G101/2),IF($I101="Reembolso",IF($R101="","",ROUND($R101-$G101,2)),IF($I101="Anulada",0,""))))))) -> 15.81 | K101: =IF(J101="","",2000+SUM(J$5:J101)) -> 2348.4 | L101: =IF(OR($I101="Ganada",$I101="Perdida",$I101="Medio Ganada",$I101="Medio Perdida"),IF($G101=0,"",J101/$G101),"") -> 0.93 | M101: =IF(OR($A101="",$B101=""),"",COUNTIFS($A$5:A101,A101,$B$5:B101,B101)) -> 1 | N101: =IF($A101="","",COUNTA($A$5:$A101)) -> 97 | O101: =IF($A101="","",COUNTA($A$5:$A101)) -> 97 | P101: =IF($K101="","",MAX($K$5:K101)) -> 2366.59 | Q101: =IF($K101="","",K101-P101) -> -18.19 | S101: =IF(OR($A101="",$F101=""),"",IF($I101="Pendiente","",ROUND($G101*($F101*0.609-1),2))) -> 2.98 | T101: =IF($A101="","",IFERROR(SUM($S$5:S101),0)) -> 140.61
A102: 46199 | B102: Winamax | C102: Union La Calera - Santiago Wanderers | D102: Totales O/U | E102: Total Under(1.5) for Team1 - regular time | F102: 1.98 | G102: 17 | H102: Normal | I102: Perdida | J102: =IF($A102="","",IF($I102="Ganada",ROUND($G102*($F102-1),2),IF($I102="Medio Ganada",ROUND($G102/2*($F102-1),2),IF($I102="Perdida",IF($H102="Free Bet",0,-$G102),IF($I102="Medio Perdida",IF($H102="Free Bet",0,-$G102/2),IF($I102="Reembolso",IF($R102="","",ROUND($R102-$G102,2)),IF($I102="Anulada",0,""))))))) -> -17 | K102: =IF(J102="","",2000+SUM(J$5:J102)) -> 2331.4 | L102: =IF(OR($I102="Ganada",$I102="Perdida",$I102="Medio Ganada",$I102="Medio Perdida"),IF($G102=0,"",J102/$G102),"") -> -1 | M102: =IF(OR($A102="",$B102=""),"",COUNTIFS($A$5:A102,A102,$B$5:B102,B102)) -> 3 | N102: =IF($A102="","",COUNTA($A$5:$A102)) -> 98 | O102: =IF($A102="","",COUNTA($A$5:$A102)) -> 98 | P102: =IF($K102="","",MAX($K$5:K102)) -> 2366.59 | Q102: =IF($K102="","",K102-P102) -> -35.19 | S102: =IF(OR($A102="",$F102=""),"",IF($I102="Pendiente","",ROUND($G102*($F102*0.609-1),2))) -> 3.5 | T102: =IF($A102="","",IFERROR(SUM($S$5:S102),0)) -> 144.11
A103: 46199 | B103: Winamax | C103: Audax Rio RJ - Resende RJ [Regular time | D103: DNB | E103: AH2(0.0)/DNB | F103: 1.43 | G103: 28 | H103: Normal | I103: Perdida | J103: =IF($A103="","",IF($I103="Ganada",ROUND($G103*($F103-1),2),IF($I103="Medio Ganada",ROUND($G103/2*($F103-1),2),IF($I103="Perdida",IF($H103="Free Bet",0,-$G103),IF($I103="Medio Perdida",IF($H103="Free Bet",0,-$G103/2),IF($I103="Reembolso",IF($R103="","",ROUND($R103-$G103,2)),IF($I103="Anulada",0,""))))))) -> -28 | K103: =IF(J103="","",2000+SUM(J$5:J103)) -> 2303.4 | L103: =IF(OR($I103="Ganada",$I103="Perdida",$I103="Medio Ganada",$I103="Medio Perdida"),IF($G103=0,"",J103/$G103),"") -> -1 | M103: =IF(OR($A103="",$B103=""),"",COUNTIFS($A$5:A103,A103,$B$5:B103,B103)) -> 4 | N103: =IF($A103="","",COUNTA($A$5:$A103)) -> 99 | O103: =IF($A103="","",COUNTA($A$5:$A103)) -> 99 | P103: =IF($K103="","",MAX($K$5:K103)) -> 2366.59 | Q103: =IF($K103="","",K103-P103) -> -63.19 | S103: =IF(OR($A103="",$F103=""),"",IF($I103="Pendiente","",ROUND($G103*($F103*0.609-1),2))) -> -3.62 | T103: =IF($A103="","",IFERROR(SUM($S$5:S103),0)) -> 140.49
A104: 46199 | B104: Pokerstars | C104: Athlone Town - Finn Harps | D104: Otro | E104: One scoreless | F104: 2.05 | G104: 17 | H104: Normal | I104: Perdida | J104: =IF($A104="","",IF($I104="Ganada",ROUND($G104*($F104-1),2),IF($I104="Medio Ganada",ROUND($G104/2*($F104-1),2),IF($I104="Perdida",IF($H104="Free Bet",0,-$G104),IF($I104="Medio Perdida",IF($H104="Free Bet",0,-$G104/2),IF($I104="Reembolso",IF($R104="","",ROUND($R104-$G104,2)),IF($I104="Anulada",0,""))))))) -> -17 | K104: =IF(J104="","",2000+SUM(J$5:J104)) -> 2286.4 | L104: =IF(OR($I104="Ganada",$I104="Perdida",$I104="Medio Ganada",$I104="Medio Perdida"),IF($G104=0,"",J104/$G104),"") -> -1 | M104: =IF(OR($A104="",$B104=""),"",COUNTIFS($A$5:A104,A104,$B$5:B104,B104)) -> 6 | N104: =IF($A104="","",COUNTA($A$5:$A104)) -> 100 | O104: =IF($A104="","",COUNTA($A$5:$A104)) -> 100 | P104: =IF($K104="","",MAX($K$5:K104)) -> 2366.59 | Q104: =IF($K104="","",K104-P104) -> -80.19 | S104: =IF(OR($A104="",$F104=""),"",IF($I104="Pendiente","",ROUND($G104*($F104*0.609-1),2))) -> 4.22 | T104: =IF($A104="","",IFERROR(SUM($S$5:S104),0)) -> 144.71
A105: 46199 | B105: Winamax | C105: Norway - France | D105: 1X2/ML | E105: 2 | F105: 1.16 | G105: 28 | H105: Normal | I105: Ganada | J105: =IF($A105="","",IF($I105="Ganada",ROUND($G105*($F105-1),2),IF($I105="Medio Ganada",ROUND($G105/2*($F105-1),2),IF($I105="Perdida",IF($H105="Free Bet",0,-$G105),IF($I105="Medio Perdida",IF($H105="Free Bet",0,-$G105/2),IF($I105="Reembolso",IF($R105="","",ROUND($R105-$G105,2)),IF($I105="Anulada",0,""))))))) -> 4.48 | K105: =IF(J105="","",2000+SUM(J$5:J105)) -> 2290.88 | L105: =IF(OR($I105="Ganada",$I105="Perdida",$I105="Medio Ganada",$I105="Medio Perdida"),IF($G105=0,"",J105/$G105),"") -> 0.16 | M105: =IF(OR($A105="",$B105=""),"",COUNTIFS($A$5:A105,A105,$B$5:B105,B105)) -> 5 | N105: =IF($A105="","",COUNTA($A$5:$A105)) -> 101 | O105: =IF($A105="","",COUNTA($A$5:$A105)) -> 101 | P105: =IF($K105="","",MAX($K$5:K105)) -> 2366.59 | Q105: =IF($K105="","",K105-P105) -> -75.71 | S105: =IF(OR($A105="",$F105=""),"",IF($I105="Pendiente","",ROUND($G105*($F105*0.609-1),2))) -> -8.22 | T105: =IF($A105="","",IFERROR(SUM($S$5:S105),0)) -> 136.49
A106: 46199 | B106: Winamax | C106: Lokomotiva Zagreb - NK Varazdin | D106: Hándicap | E106: Asian Handicap1(0) - 1st | F106: 1.9 | G106: 17 | H106: Normal | I106: Ganada | J106: =IF($A106="","",IF($I106="Ganada",ROUND($G106*($F106-1),2),IF($I106="Medio Ganada",ROUND($G106/2*($F106-1),2),IF($I106="Perdida",IF($H106="Free Bet",0,-$G106),IF($I106="Medio Perdida",IF($H106="Free Bet",0,-$G106/2),IF($I106="Reembolso",IF($R106="","",ROUND($R106-$G106,2)),IF($I106="Anulada",0,""))))))) -> 15.3 | K106: =IF(J106="","",2000+SUM(J$5:J106)) -> 2306.18 | L106: =IF(OR($I106="Ganada",$I106="Perdida",$I106="Medio Ganada",$I106="Medio Perdida"),IF($G106=0,"",J106/$G106),"") -> 0.9 | M106: =IF(OR($A106="",$B106=""),"",COUNTIFS($A$5:A106,A106,$B$5:B106,B106)) -> 6 | N106: =IF($A106="","",COUNTA($A$5:$A106)) -> 102 | O106: =IF($A106="","",COUNTA($A$5:$A106)) -> 102 | P106: =IF($K106="","",MAX($K$5:K106)) -> 2366.59 | Q106: =IF($K106="","",K106-P106) -> -60.41 | S106: =IF(OR($A106="",$F106=""),"",IF($I106="Pendiente","",ROUND($G106*($F106*0.609-1),2))) -> 2.67 | T106: =IF($A106="","",IFERROR(SUM($S$5:S106),0)) -> 139.16
A107: 46199 | B107: Winamax | C107: Heidelberg United Women - Boroondara Eagles FC Women | D107: Hándicap | E107: Asian Handicap1(0.25) - 1st | F107: 1.68 | G107: 23 | H107: Normal | I107: Perdida | J107: =IF($A107="","",IF($I107="Ganada",ROUND($G107*($F107-1),2),IF($I107="Medio Ganada",ROUND($G107/2*($F107-1),2),IF($I107="Perdida",IF($H107="Free Bet",0,-$G107),IF($I107="Medio Perdida",IF($H107="Free Bet",0,-$G107/2),IF($I107="Reembolso",IF($R107="","",ROUND($R107-$G107,2)),IF($I107="Anulada",0,""))))))) -> -23 | K107: =IF(J107="","",2000+SUM(J$5:J107)) -> 2283.18 | L107: =IF(OR($I107="Ganada",$I107="Perdida",$I107="Medio Ganada",$I107="Medio Perdida"),IF($G107=0,"",J107/$G107),"") -> -1 | M107: =IF(OR($A107="",$B107=""),"",COUNTIFS($A$5:A107,A107,$B$5:B107,B107)) -> 7 | N107: =IF($A107="","",COUNTA($A$5:$A107)) -> 103 | O107: =IF($A107="","",COUNTA($A$5:$A107)) -> 103 | P107: =IF($K107="","",MAX($K$5:K107)) -> 2366.59 | Q107: =IF($K107="","",K107-P107) -> -83.41 | S107: =IF(OR($A107="",$F107=""),"",IF($I107="Pendiente","",ROUND($G107*($F107*0.609-1),2))) -> 0.53 | T107: =IF($A107="","",IFERROR(SUM($S$5:S107),0)) -> 139.69
A108: 46199 | B108: Pokerstars | C108: Bohemians Dublin - St. Patricks Athletic | D108: Totales O/U | E108: Total Under(2.5) | F108: 1.86 | G108: 17 | H108: Normal | I108: Ganada | J108: =IF($A108="","",IF($I108="Ganada",ROUND($G108*($F108-1),2),IF($I108="Medio Ganada",ROUND($G108/2*($F108-1),2),IF($I108="Perdida",IF($H108="Free Bet",0,-$G108),IF($I108="Medio Perdida",IF($H108="Free Bet",0,-$G108/2),IF($I108="Reembolso",IF($R108="","",ROUND($R108-$G108,2)),IF($I108="Anulada",0,""))))))) -> 14.62 | K108: =IF(J108="","",2000+SUM(J$5:J108)) -> 2297.8 | L108: =IF(OR($I108="Ganada",$I108="Perdida",$I108="Medio Ganada",$I108="Medio Perdida"),IF($G108=0,"",J108/$G108),"") -> 0.86 | M108: =IF(OR($A108="",$B108=""),"",COUNTIFS($A$5:A108,A108,$B$5:B108,B108)) -> 7 | N108: =IF($A108="","",COUNTA($A$5:$A108)) -> 104 | O108: =IF($A108="","",COUNTA($A$5:$A108)) -> 104 | P108: =IF($K108="","",MAX($K$5:K108)) -> 2366.59 | Q108: =IF($K108="","",K108-P108) -> -68.79 | S108: =IF(OR($A108="",$F108=""),"",IF($I108="Pendiente","",ROUND($G108*($F108*0.609-1),2))) -> 2.26 | T108: =IF($A108="","",IFERROR(SUM($S$5:S108),0)) -> 141.95
A109: 46199 | B109: Winamax | C109: NEW VISION – Julie&cie | D109: Hándicap | E109: Hándicap asiático 1 -1.5 mapa | F109: 1.7 | G109: 28 | H109: Normal | I109: Perdida | J109: =IF($A109="","",IF($I109="Ganada",ROUND($G109*($F109-1),2),IF($I109="Medio Ganada",ROUND($G109/2*($F109-1),2),IF($I109="Perdida",IF($H109="Free Bet",0,-$G109),IF($I109="Medio Perdida",IF($H109="Free Bet",0,-$G109/2),IF($I109="Reembolso",IF($R109="","",ROUND($R109-$G109,2)),IF($I109="Anulada",0,""))))))) -> -28 | K109: =IF(J109="","",2000+SUM(J$5:J109)) -> 2269.8 | L109: =IF(OR($I109="Ganada",$I109="Perdida",$I109="Medio Ganada",$I109="Medio Perdida"),IF($G109=0,"",J109/$G109),"") -> -1 | M109: =IF(OR($A109="",$B109=""),"",COUNTIFS($A$5:A109,A109,$B$5:B109,B109)) -> 8 | N109: =IF($A109="","",COUNTA($A$5:$A109)) -> 105 | O109: =IF($A109="","",COUNTA($A$5:$A109)) -> 105 | P109: =IF($K109="","",MAX($K$5:K109)) -> 2366.59 | Q109: =IF($K109="","",K109-P109) -> -96.79 | S109: =IF(OR($A109="",$F109=""),"",IF($I109="Pendiente","",ROUND($G109*($F109*0.609-1),2))) -> 0.99 | T109: =IF($A109="","",IFERROR(SUM($S$5:S109),0)) -> 142.94
A110: 46199 | B110: Winamax | C110: Povazska Bystrica – FC Banik Ostrava B | D110: DNB | E110: 2 | F110: 1.8 | G110: 28 | H110: Normal | I110: Ganada | J110: =IF($A110="","",IF($I110="Ganada",ROUND($G110*($F110-1),2),IF($I110="Medio Ganada",ROUND($G110/2*($F110-1),2),IF($I110="Perdida",IF($H110="Free Bet",0,-$G110),IF($I110="Medio Perdida",IF($H110="Free Bet",0,-$G110/2),IF($I110="Reembolso",IF($R110="","",ROUND($R110-$G110,2)),IF($I110="Anulada",0,""))))))) -> 22.4 | K110: =IF(J110="","",2000+SUM(J$5:J110)) -> 2292.2 | L110: =IF(OR($I110="Ganada",$I110="Perdida",$I110="Medio Ganada",$I110="Medio Perdida"),IF($G110=0,"",J110/$G110),"") -> 0.8 | M110: =IF(OR($A110="",$B110=""),"",COUNTIFS($A$5:A110,A110,$B$5:B110,B110)) -> 9 | N110: =IF($A110="","",COUNTA($A$5:$A110)) -> 106 | O110: =IF($A110="","",COUNTA($A$5:$A110)) -> 106 | P110: =IF($K110="","",MAX($K$5:K110)) -> 2366.59 | Q110: =IF($K110="","",K110-P110) -> -74.39 | S110: =IF(OR($A110="",$F110=""),"",IF($I110="Pendiente","",ROUND($G110*($F110*0.609-1),2))) -> 2.69 | T110: =IF($A110="","",IFERROR(SUM($S$5:S110),0)) -> 145.63
A111: 46200 | B111: GoldenBull | C111: Novorizontino-SP - Vila Nova-GO | D111: Totales O/U | E111: Total Under(1.5) for Team2 - regular time | F111: 1.76 | G111: 23 | H111: Normal | I111: Ganada | J111: =IF($A111="","",IF($I111="Ganada",ROUND($G111*($F111-1),2),IF($I111="Medio Ganada",ROUND($G111/2*($F111-1),2),IF($I111="Perdida",IF($H111="Free Bet",0,-$G111),IF($I111="Medio Perdida",IF($H111="Free Bet",0,-$G111/2),IF($I111="Reembolso",IF($R111="","",ROUND($R111-$G111,2)),IF($I111="Anulada",0,""))))))) -> 17.48 | K111: =IF(J111="","",2000+SUM(J$5:J111)) -> 2309.68 | L111: =IF(OR($I111="Ganada",$I111="Perdida",$I111="Medio Ganada",$I111="Medio Perdida"),IF($G111=0,"",J111/$G111),"") -> 0.76 | M111: =IF(OR($A111="",$B111=""),"",COUNTIFS($A$5:A111,A111,$B$5:B111,B111)) -> 1 | N111: =IF($A111="","",COUNTA($A$5:$A111)) -> 107 | O111: =IF($A111="","",COUNTA($A$5:$A111)) -> 107 | P111: =IF($K111="","",MAX($K$5:K111)) -> 2366.59 | Q111: =IF($K111="","",K111-P111) -> -56.91 | S111: =IF(OR($A111="",$F111=""),"",IF($I111="Pendiente","",ROUND($G111*($F111*0.609-1),2))) -> 1.65 | T111: =IF($A111="","",IFERROR(SUM($S$5:S111),0)) -> 147.28
A112: 46200 | B112: GoldenBull | C112: Chicago Sky (W) - Portland Fire (W | D112: Totales O/U | E112: Total Over(85.5) for Team2 - with OT | F112: 2.07 | G112: 17 | H112: Normal | I112: Ganada | J112: =IF($A112="","",IF($I112="Ganada",ROUND($G112*($F112-1),2),IF($I112="Medio Ganada",ROUND($G112/2*($F112-1),2),IF($I112="Perdida",IF($H112="Free Bet",0,-$G112),IF($I112="Medio Perdida",IF($H112="Free Bet",0,-$G112/2),IF($I112="Reembolso",IF($R112="","",ROUND($R112-$G112,2)),IF($I112="Anulada",0,""))))))) -> 18.19 | K112: =IF(J112="","",2000+SUM(J$5:J112)) -> 2327.87 | L112: =IF(OR($I112="Ganada",$I112="Perdida",$I112="Medio Ganada",$I112="Medio Perdida"),IF($G112=0,"",J112/$G112),"") -> 1.07 | M112: =IF(OR($A112="",$B112=""),"",COUNTIFS($A$5:A112,A112,$B$5:B112,B112)) -> 2 | N112: =IF($A112="","",COUNTA($A$5:$A112)) -> 108 | O112: =IF($A112="","",COUNTA($A$5:$A112)) -> 108 | P112: =IF($K112="","",MAX($K$5:K112)) -> 2366.59 | Q112: =IF($K112="","",K112-P112) -> -38.72 | S112: =IF(OR($A112="",$F112=""),"",IF($I112="Pendiente","",ROUND($G112*($F112*0.609-1),2))) -> 4.43 | T112: =IF($A112="","",IFERROR(SUM($S$5:S112),0)) -> 151.71
A113: 46200 | B113: GoldenBull | C113: Detroit Tigers - Houston Astros | D113: Totales O/U | E113: Total Over(9.5) for Team1 - with OT | F113: 1.85 | G113: 17 | H113: Normal | I113: Perdida | J113: =IF($A113="","",IF($I113="Ganada",ROUND($G113*($F113-1),2),IF($I113="Medio Ganada",ROUND($G113/2*($F113-1),2),IF($I113="Perdida",IF($H113="Free Bet",0,-$G113),IF($I113="Medio Perdida",IF($H113="Free Bet",0,-$G113/2),IF($I113="Reembolso",IF($R113="","",ROUND($R113-$G113,2)),IF($I113="Anulada",0,""))))))) -> -17 | K113: =IF(J113="","",2000+SUM(J$5:J113)) -> 2310.87 | L113: =IF(OR($I113="Ganada",$I113="Perdida",$I113="Medio Ganada",$I113="Medio Perdida"),IF($G113=0,"",J113/$G113),"") -> -1 | M113: =IF(OR($A113="",$B113=""),"",COUNTIFS($A$5:A113,A113,$B$5:B113,B113)) -> 3 | N113: =IF($A113="","",COUNTA($A$5:$A113)) -> 109 | O113: =IF($A113="","",COUNTA($A$5:$A113)) -> 109 | P113: =IF($K113="","",MAX($K$5:K113)) -> 2366.59 | Q113: =IF($K113="","",K113-P113) -> -55.72 | S113: =IF(OR($A113="",$F113=""),"",IF($I113="Pendiente","",ROUND($G113*($F113*0.609-1),2))) -> 2.15 | T113: =IF($A113="","",IFERROR(SUM($S$5:S113),0)) -> 153.86
A114: 46200 | B114: GoldenBull | C114: ga FC Kunoichi (F) - Viamaterasu Miyazaki (F) | D114: Totales O/U | E114: Menos de 0.5 goles | F114: 2.55 | G114: 10 | H114: Free Bet | I114: Ganada | J114: =IF($A114="","",IF($I114="Ganada",ROUND($G114*($F114-1),2),IF($I114="Medio Ganada",ROUND($G114/2*($F114-1),2),IF($I114="Perdida",IF($H114="Free Bet",0,-$G114),IF($I114="Medio Perdida",IF($H114="Free Bet",0,-$G114/2),IF($I114="Reembolso",IF($R114="","",ROUND($R114-$G114,2)),IF($I114="Anulada",0,""))))))) -> 15.5 | K114: =IF(J114="","",2000+SUM(J$5:J114)) -> 2326.37 | L114: =IF(OR($I114="Ganada",$I114="Perdida",$I114="Medio Ganada",$I114="Medio Perdida"),IF($G114=0,"",J114/$G114),"") -> 1.55 | M114: =IF(OR($A114="",$B114=""),"",COUNTIFS($A$5:A114,A114,$B$5:B114,B114)) -> 4 | N114: =IF($A114="","",COUNTA($A$5:$A114)) -> 110 | O114: =IF($A114="","",COUNTA($A$5:$A114)) -> 110 | P114: =IF($K114="","",MAX($K$5:K114)) -> 2366.59 | Q114: =IF($K114="","",K114-P114) -> -40.22 | S114: =IF(OR($A114="",$F114=""),"",IF($I114="Pendiente","",ROUND($G114*($F114*0.609-1),2))) -> 5.53 | T114: =IF($A114="","",IFERROR(SUM($S$5:S114),0)) -> 159.39
A115: 46200 | B115: Yosport | C115: Alana Subasic - Kateryna Lazarenko | D115: 1X2/ML | E115: Team1 Win - regular time | F115: 1.3 | G115: 34 | H115: Normal | I115: Ganada | J115: =IF($A115="","",IF($I115="Ganada",ROUND($G115*($F115-1),2),IF($I115="Medio Ganada",ROUND($G115/2*($F115-1),2),IF($I115="Perdida",IF($H115="Free Bet",0,-$G115),IF($I115="Medio Perdida",IF($H115="Free Bet",0,-$G115/2),IF($I115="Reembolso",IF($R115="","",ROUND($R115-$G115,2)),IF($I115="Anulada",0,""))))))) -> 10.2 | K115: =IF(J115="","",2000+SUM(J$5:J115)) -> 2336.57 | L115: =IF(OR($I115="Ganada",$I115="Perdida",$I115="Medio Ganada",$I115="Medio Perdida"),IF($G115=0,"",J115/$G115),"") -> 0.3 | M115: =IF(OR($A115="",$B115=""),"",COUNTIFS($A$5:A115,A115,$B$5:B115,B115)) -> 1 | N115: =IF($A115="","",COUNTA($A$5:$A115)) -> 111 | O115: =IF($A115="","",COUNTA($A$5:$A115)) -> 111 | P115: =IF($K115="","",MAX($K$5:K115)) -> 2366.59 | Q115: =IF($K115="","",K115-P115) -> -30.02 | S115: =IF(OR($A115="",$F115=""),"",IF($I115="Pendiente","",ROUND($G115*($F115*0.609-1),2))) -> -7.08 | T115: =IF($A115="","",IFERROR(SUM($S$5:S115),0)) -> 152.31
A116: 46200 | B116: Yosport | C116: Beijing Guoan - Wuhan Three Towns | D116: 1X2/ML | E116: 1 | F116: 1.64 | G116: 15 | H116: Normal | I116: Ganada | J116: =IF($A116="","",IF($I116="Ganada",ROUND($G116*($F116-1),2),IF($I116="Medio Ganada",ROUND($G116/2*($F116-1),2),IF($I116="Perdida",IF($H116="Free Bet",0,-$G116),IF($I116="Medio Perdida",IF($H116="Free Bet",0,-$G116/2),IF($I116="Reembolso",IF($R116="","",ROUND($R116-$G116,2)),IF($I116="Anulada",0,""))))))) -> 9.6 | K116: =IF(J116="","",2000+SUM(J$5:J116)) -> 2346.17 | L116: =IF(OR($I116="Ganada",$I116="Perdida",$I116="Medio Ganada",$I116="Medio Perdida"),IF($G116=0,"",J116/$G116),"") -> 0.64 | M116: =IF(OR($A116="",$B116=""),"",COUNTIFS($A$5:A116,A116,$B$5:B116,B116)) -> 2 | N116: =IF($A116="","",COUNTA($A$5:$A116)) -> 112 | O116: =IF($A116="","",COUNTA($A$5:$A116)) -> 112 | P116: =IF($K116="","",MAX($K$5:K116)) -> 2366.59 | Q116: =IF($K116="","",K116-P116) -> -20.42 | S116: =IF(OR($A116="",$F116=""),"",IF($I116="Pendiente","",ROUND($G116*($F116*0.609-1),2))) -> -0.02 | T116: =IF($A116="","",IFERROR(SUM($S$5:S116),0)) -> 152.29
A117: 46200 | B117: SpeedyBet | C117: Ljungskile SK - Örebro SK | D117: Totales O/U | E117: Total Over(8.5) - Corners - regular time | F117: 1.85 | G117: 17 | H117: Normal | I117: Ganada | J117: =IF($A117="","",IF($I117="Ganada",ROUND($G117*($F117-1),2),IF($I117="Medio Ganada",ROUND($G117/2*($F117-1),2),IF($I117="Perdida",IF($H117="Free Bet",0,-$G117),IF($I117="Medio Perdida",IF($H117="Free Bet",0,-$G117/2),IF($I117="Reembolso",IF($R117="","",ROUND($R117-$G117,2)),IF($I117="Anulada",0,""))))))) -> 14.45 | K117: =IF(J117="","",2000+SUM(J$5:J117)) -> 2360.62 | L117: =IF(OR($I117="Ganada",$I117="Perdida",$I117="Medio Ganada",$I117="Medio Perdida"),IF($G117=0,"",J117/$G117),"") -> 0.85 | M117: =IF(OR($A117="",$B117=""),"",COUNTIFS($A$5:A117,A117,$B$5:B117,B117)) -> 1 | N117: =IF($A117="","",COUNTA($A$5:$A117)) -> 113 | O117: =IF($A117="","",COUNTA($A$5:$A117)) -> 113 | P117: =IF($K117="","",MAX($K$5:K117)) -> 2366.59 | Q117: =IF($K117="","",K117-P117) -> -5.97 | S117: =IF(OR($A117="",$F117=""),"",IF($I117="Pendiente","",ROUND($G117*($F117*0.609-1),2))) -> 2.15 | T117: =IF($A117="","",IFERROR(SUM($S$5:S117),0)) -> 154.44
A118: 46200 | B118: SpeedyBet | C118: Zhetysu Taldykorgan - FK Aktobe | D118: Totales O/U | E118: Total Under(0.5) for Team2 - regular time | F118: 2.07 | G118: 17 | H118: Normal | I118: Ganada | J118: =IF($A118="","",IF($I118="Ganada",ROUND($G118*($F118-1),2),IF($I118="Medio Ganada",ROUND($G118/2*($F118-1),2),IF($I118="Perdida",IF($H118="Free Bet",0,-$G118),IF($I118="Medio Perdida",IF($H118="Free Bet",0,-$G118/2),IF($I118="Reembolso",IF($R118="","",ROUND($R118-$G118,2)),IF($I118="Anulada",0,""))))))) -> 18.19 | K118: =IF(J118="","",2000+SUM(J$5:J118)) -> 2378.81 | L118: =IF(OR($I118="Ganada",$I118="Perdida",$I118="Medio Ganada",$I118="Medio Perdida"),IF($G118=0,"",J118/$G118),"") -> 1.07 | M118: =IF(OR($A118="",$B118=""),"",COUNTIFS($A$5:A118,A118,$B$5:B118,B118)) -> 2 | N118: =IF($A118="","",COUNTA($A$5:$A118)) -> 114 | O118: =IF($A118="","",COUNTA($A$5:$A118)) -> 114 | P118: =IF($K118="","",MAX($K$5:K118)) -> 2378.81 | Q118: =IF($K118="","",K118-P118) -> 0 | S118: =IF(OR($A118="",$F118=""),"",IF($I118="Pendiente","",ROUND($G118*($F118*0.609-1),2))) -> 4.43 | T118: =IF($A118="","",IFERROR(SUM($S$5:S118),0)) -> 158.87
A119: 46200 | B119: Paf | C119: HJK Helsinki - KuPS | D119: Hándicap | E119: Asian Handicap2(-0.5) | F119: 1.75 | G119: 5 | H119: Free Bet | I119: Ganada | J119: =IF($A119="","",IF($I119="Ganada",ROUND($G119*($F119-1),2),IF($I119="Medio Ganada",ROUND($G119/2*($F119-1),2),IF($I119="Perdida",IF($H119="Free Bet",0,-$G119),IF($I119="Medio Perdida",IF($H119="Free Bet",0,-$G119/2),IF($I119="Reembolso",IF($R119="","",ROUND($R119-$G119,2)),IF($I119="Anulada",0,""))))))) -> 3.75 | K119: =IF(J119="","",2000+SUM(J$5:J119)) -> 2382.56 | L119: =IF(OR($I119="Ganada",$I119="Perdida",$I119="Medio Ganada",$I119="Medio Perdida"),IF($G119=0,"",J119/$G119),"") -> 0.75 | M119: =IF(OR($A119="",$B119=""),"",COUNTIFS($A$5:A119,A119,$B$5:B119,B119)) -> 1 | N119: =IF($A119="","",COUNTA($A$5:$A119)) -> 115 | O119: =IF($A119="","",COUNTA($A$5:$A119)) -> 115 | P119: =IF($K119="","",MAX($K$5:K119)) -> 2382.56 | Q119: =IF($K119="","",K119-P119) -> 0 | S119: =IF(OR($A119="",$F119=""),"",IF($I119="Pendiente","",ROUND($G119*($F119*0.609-1),2))) -> 0.33 | T119: =IF($A119="","",IFERROR(SUM($S$5:S119),0)) -> 159.2
A120: 46200 | B120: Paf | C120: Inter de Limeira-SP - Maringá-PR | D120: Totales O/U | E120: Total Under(2.5) - regular time | F120: 1.64 | G120: 23 | H120: Normal | I120: Perdida | J120: =IF($A120="","",IF($I120="Ganada",ROUND($G120*($F120-1),2),IF($I120="Medio Ganada",ROUND($G120/2*($F120-1),2),IF($I120="Perdida",IF($H120="Free Bet",0,-$G120),IF($I120="Medio Perdida",IF($H120="Free Bet",0,-$G120/2),IF($I120="Reembolso",IF($R120="","",ROUND($R120-$G120,2)),IF($I120="Anulada",0,""))))))) -> -23 | K120: =IF(J120="","",2000+SUM(J$5:J120)) -> 2359.56 | L120: =IF(OR($I120="Ganada",$I120="Perdida",$I120="Medio Ganada",$I120="Medio Perdida"),IF($G120=0,"",J120/$G120),"") -> -1 | M120: =IF(OR($A120="",$B120=""),"",COUNTIFS($A$5:A120,A120,$B$5:B120,B120)) -> 2 | N120: =IF($A120="","",COUNTA($A$5:$A120)) -> 116 | O120: =IF($A120="","",COUNTA($A$5:$A120)) -> 116 | P120: =IF($K120="","",MAX($K$5:K120)) -> 2382.56 | Q120: =IF($K120="","",K120-P120) -> -23 | S120: =IF(OR($A120="",$F120=""),"",IF($I120="Pendiente","",ROUND($G120*($F120*0.609-1),2))) -> -0.03 | T120: =IF($A120="","",IFERROR(SUM($S$5:S120),0)) -> 159.17
...

Sheet Gráficas
A1: Evolución del Bankroll
A42: Drawdown — Picos y Valles
A84: EV+ Histórico Acumulado
A126: Beneficio por Casa (€)
